2019-04-02 12:29:09,257 ERROR: Exception on /favicon.ico [GET] [in /home/python/.virtualenvs/flask/local/lib/python2.7/site-packages/flask/app.py:1761]
Traceback (most recent call last):
  File "/home/python/.virtualenvs/flask/local/lib/python2.7/site-packages/flask/app.py", line 2292, in wsgi_app
    response = self.full_dispatch_request()
  File "/home/python/.virtualenvs/flask/local/lib/python2.7/site-packages/flask/app.py", line 1815, in full_dispatch_request
    rv = self.handle_user_exception(e)
  File "/home/python/.virtualenvs/flask/local/lib/python2.7/site-packages/flask/app.py", line 1713, in handle_user_exception
    return self.handle_http_exception(e)
  File "/home/python/.virtualenvs/flask/local/lib/python2.7/site-packages/flask/app.py", line 1644, in handle_http_exception
    return handler(e)
  File "/home/python/workspace/microblog/app/errors/handlers.py", line 9, in not_found_error
    return render_template('errors/404.html'),404
  File "/home/python/.virtualenvs/flask/local/lib/python2.7/site-packages/flask/templating.py", line 135, in render_template
    context, ctx.app)
  File "/home/python/.virtualenvs/flask/local/lib/python2.7/site-packages/flask/templating.py", line 117, in _render
    rv = template.render(context)
  File "/home/python/.virtualenvs/flask/local/lib/python2.7/site-packages/jinja2/environment.py", line 1008, in render
    return self.environment.handle_exception(exc_info, True)
  File "/home/python/.virtualenvs/flask/local/lib/python2.7/site-packages/jinja2/environment.py", line 780, in handle_exception
    reraise(exc_type, exc_value, tb)
  File "/home/python/workspace/microblog/app/templates/errors/404.html", line 1, in top-level template code
    {% extends "base.html" %}
  File "/home/python/workspace/microblog/app/templates/base.html", line 1, in top-level template code
    {% extends "bootstrap/base.html" %}
  File "/home/python/.virtualenvs/flask/local/lib/python2.7/site-packages/flask_bootstrap/templates/bootstrap/base.html", line 1, in top-level template code
    {% block doc -%}
  File "/home/python/.virtualenvs/flask/local/lib/python2.7/site-packages/flask_bootstrap/templates/bootstrap/base.html", line 4, in block "doc"
    {%- block html %}
  File "/home/python/.virtualenvs/flask/local/lib/python2.7/site-packages/flask_bootstrap/templates/bootstrap/base.html", line 20, in block "html"
    {% block body -%}
  File "/home/python/.virtualenvs/flask/local/lib/python2.7/site-packages/flask_bootstrap/templates/bootstrap/base.html", line 21, in block "body"
    {% block navbar %}
  File "/home/python/workspace/microblog/app/templates/base.html", line 31, in block "navbar"
    <li><a href="{{ url_for('main.logout') }}">{{ _('Logout')}}</a></li>
  File "/home/python/.virtualenvs/flask/local/lib/python2.7/site-packages/flask/helpers.py", line 356, in url_for
    return appctx.app.handle_url_build_error(error, endpoint, values)
  File "/home/python/.virtualenvs/flask/local/lib/python2.7/site-packages/flask/app.py", line 2061, in handle_url_build_error
    reraise(exc_type, exc_value, tb)
  File "/home/python/.virtualenvs/flask/local/lib/python2.7/site-packages/flask/helpers.py", line 345, in url_for
    force_external=external)
  File "/home/python/.virtualenvs/flask/local/lib/python2.7/site-packages/werkzeug/routing.py", line 1776, in build
    raise BuildError(endpoint, values, method, self)
BuildError: Could not build url for endpoint 'main.logout'. Did you mean 'auth.logout' instead?
2019-04-02 12:29:29,946 INFO: Microblog startup [in /home/python/workspace/microblog/app/__init__.py:85]
2019-04-02 12:29:35,751 ERROR: Exception on /favicon.ico [GET] [in /home/python/.virtualenvs/flask/local/lib/python2.7/site-packages/flask/app.py:1761]
Traceback (most recent call last):
  File "/home/python/.virtualenvs/flask/local/lib/python2.7/site-packages/flask/app.py", line 2292, in wsgi_app
    response = self.full_dispatch_request()
  File "/home/python/.virtualenvs/flask/local/lib/python2.7/site-packages/flask/app.py", line 1815, in full_dispatch_request
    rv = self.handle_user_exception(e)
  File "/home/python/.virtualenvs/flask/local/lib/python2.7/site-packages/flask/app.py", line 1713, in handle_user_exception
    return self.handle_http_exception(e)
  File "/home/python/.virtualenvs/flask/local/lib/python2.7/site-packages/flask/app.py", line 1644, in handle_http_exception
    return handler(e)
  File "/home/python/workspace/microblog/app/errors/handlers.py", line 9, in not_found_error
    return render_template('errors/404.html'),404
  File "/home/python/.virtualenvs/flask/local/lib/python2.7/site-packages/flask/templating.py", line 135, in render_template
    context, ctx.app)
  File "/home/python/.virtualenvs/flask/local/lib/python2.7/site-packages/flask/templating.py", line 117, in _render
    rv = template.render(context)
  File "/home/python/.virtualenvs/flask/local/lib/python2.7/site-packages/jinja2/environment.py", line 1008, in render
    return self.environment.handle_exception(exc_info, True)
  File "/home/python/.virtualenvs/flask/local/lib/python2.7/site-packages/jinja2/environment.py", line 780, in handle_exception
    reraise(exc_type, exc_value, tb)
  File "/home/python/workspace/microblog/app/templates/errors/404.html", line 1, in top-level template code
    {% extends "base.html" %}
  File "/home/python/workspace/microblog/app/templates/base.html", line 1, in top-level template code
    {% extends "bootstrap/base.html" %}
  File "/home/python/.virtualenvs/flask/local/lib/python2.7/site-packages/flask_bootstrap/templates/bootstrap/base.html", line 1, in top-level template code
    {% block doc -%}
  File "/home/python/.virtualenvs/flask/local/lib/python2.7/site-packages/flask_bootstrap/templates/bootstrap/base.html", line 4, in block "doc"
    {%- block html %}
  File "/home/python/.virtualenvs/flask/local/lib/python2.7/site-packages/flask_bootstrap/templates/bootstrap/base.html", line 20, in block "html"
    {% block body -%}
  File "/home/python/.virtualenvs/flask/local/lib/python2.7/site-packages/flask_bootstrap/templates/bootstrap/base.html", line 23, in block "body"
    {% block content -%}
  File "/home/python/workspace/microblog/app/templates/base.html", line 50, in block "content"
    {% block app_content %}{% endblock %}
  File "/home/python/workspace/microblog/app/templates/errors/404.html", line 6, in block "app_content"
    <a href="{{ url_for('index') }}">Back</a>
  File "/home/python/.virtualenvs/flask/local/lib/python2.7/site-packages/flask/helpers.py", line 356, in url_for
    return appctx.app.handle_url_build_error(error, endpoint, values)
  File "/home/python/.virtualenvs/flask/local/lib/python2.7/site-packages/flask/app.py", line 2061, in handle_url_build_error
    reraise(exc_type, exc_value, tb)
  File "/home/python/.virtualenvs/flask/local/lib/python2.7/site-packages/flask/helpers.py", line 345, in url_for
    force_external=external)
  File "/home/python/.virtualenvs/flask/local/lib/python2.7/site-packages/werkzeug/routing.py", line 1776, in build
    raise BuildError(endpoint, values, method, self)
BuildError: Could not build url for endpoint 'index'. Did you mean 'main.index' instead?
