2019-04-02 12:48:21,912 ERROR: Exception on /user/aaajjj1627 [GET] [in /home/python/.virtualenvs/flask/local/lib/python2.7/site-packages/flask/app.py:1761]
Traceback (most recent call last):
  File "/home/python/.virtualenvs/flask/local/lib/python2.7/site-packages/flask/app.py", line 2292, in wsgi_app
    response = self.full_dispatch_request()
  File "/home/python/.virtualenvs/flask/local/lib/python2.7/site-packages/flask/app.py", line 1815, in full_dispatch_request
    rv = self.handle_user_exception(e)
  File "/home/python/.virtualenvs/flask/local/lib/python2.7/site-packages/flask/app.py", line 1718, in handle_user_exception
    reraise(exc_type, exc_value, tb)
  File "/home/python/.virtualenvs/flask/local/lib/python2.7/site-packages/flask/app.py", line 1813, in full_dispatch_request
    rv = self.dispatch_request()
  File "/home/python/.virtualenvs/flask/local/lib/python2.7/site-packages/flask/app.py", line 1799, in dispatch_request
    return self.view_functions[rule.endpoint](**req.view_args)
  File "/home/python/.virtualenvs/flask/local/lib/python2.7/site-packages/flask_login/utils.py", line 261, in decorated_view
    return func(*args, **kwargs)
  File "/home/python/workspace/microblog/app/main/routes.py", line 78, in user
    next_url=next_url, prev_url=prev_url)
  File "/home/python/.virtualenvs/flask/local/lib/python2.7/site-packages/flask/templating.py", line 135, in render_template
    context, ctx.app)
  File "/home/python/.virtualenvs/flask/local/lib/python2.7/site-packages/flask/templating.py", line 117, in _render
    rv = template.render(context)
  File "/home/python/.virtualenvs/flask/local/lib/python2.7/site-packages/jinja2/environment.py", line 1008, in render
    return self.environment.handle_exception(exc_info, True)
  File "/home/python/.virtualenvs/flask/local/lib/python2.7/site-packages/jinja2/environment.py", line 780, in handle_exception
    reraise(exc_type, exc_value, tb)
  File "/home/python/workspace/microblog/app/templates/user.html", line 1, in top-level template code
    {% extends "base.html" %}
  File "/home/python/workspace/microblog/app/templates/base.html", line 1, in top-level template code
    {% extends "bootstrap/base.html" %}
  File "/home/python/.virtualenvs/flask/local/lib/python2.7/site-packages/flask_bootstrap/templates/bootstrap/base.html", line 1, in top-level template code
    {% block doc -%}
  File "/home/python/.virtualenvs/flask/local/lib/python2.7/site-packages/flask_bootstrap/templates/bootstrap/base.html", line 4, in block "doc"
    {%- block html %}
  File "/home/python/.virtualenvs/flask/local/lib/python2.7/site-packages/flask_bootstrap/templates/bootstrap/base.html", line 20, in block "html"
    {% block body -%}
  File "/home/python/.virtualenvs/flask/local/lib/python2.7/site-packages/flask_bootstrap/templates/bootstrap/base.html", line 23, in block "body"
    {% block content -%}
  File "/home/python/workspace/microblog/app/templates/base.html", line 50, in block "content"
    {% block app_content %}{% endblock %}
  File "/home/python/workspace/microblog/app/templates/user.html", line 16, in block "app_content"
    {% if not current_user.get_task_in_progress('export_posts') %}
UndefinedError: 'app.models.User object' has no attribute 'get_task_in_progress'
2019-04-02 12:49:46,177 INFO: Microblog startup [in /home/python/workspace/microblog/app/__init__.py:85]
2019-04-02 12:50:30,341 ERROR: Exception on /auth/reset_password_request [POST] [in /home/python/.virtualenvs/flask/local/lib/python2.7/site-packages/flask/app.py:1761]
Traceback (most recent call last):
  File "/home/python/.virtualenvs/flask/local/lib/python2.7/site-packages/flask/app.py", line 2292, in wsgi_app
    response = self.full_dispatch_request()
  File "/home/python/.virtualenvs/flask/local/lib/python2.7/site-packages/flask/app.py", line 1815, in full_dispatch_request
    rv = self.handle_user_exception(e)
  File "/home/python/.virtualenvs/flask/local/lib/python2.7/site-packages/flask/app.py", line 1718, in handle_user_exception
    reraise(exc_type, exc_value, tb)
  File "/home/python/.virtualenvs/flask/local/lib/python2.7/site-packages/flask/app.py", line 1813, in full_dispatch_request
    rv = self.dispatch_request()
  File "/home/python/.virtualenvs/flask/local/lib/python2.7/site-packages/flask/app.py", line 1799, in dispatch_request
    return self.view_functions[rule.endpoint](**req.view_args)
  File "/home/python/workspace/microblog/app/auth/routes.py", line 60, in reset_password_request
    send_password_reset_email(user)
  File "/home/python/workspace/microblog/app/auth/email.py", line 7, in send_password_reset_email
    token = user.get_reset_password_token()
  File "/home/python/workspace/microblog/app/models.py", line 69, in get_reset_password_token
    app.config['SECRET_KEY'], algorithm='HS256').decode('utf-8')
NameError: global name 'app' is not defined
2019-04-02 12:50:40,847 ERROR: Exception on /auth/reset_password_request [POST] [in /home/python/.virtualenvs/flask/local/lib/python2.7/site-packages/flask/app.py:1761]
Traceback (most recent call last):
  File "/home/python/.virtualenvs/flask/local/lib/python2.7/site-packages/flask/app.py", line 2292, in wsgi_app
    response = self.full_dispatch_request()
  File "/home/python/.virtualenvs/flask/local/lib/python2.7/site-packages/flask/app.py", line 1815, in full_dispatch_request
    rv = self.handle_user_exception(e)
  File "/home/python/.virtualenvs/flask/local/lib/python2.7/site-packages/flask/app.py", line 1718, in handle_user_exception
    reraise(exc_type, exc_value, tb)
  File "/home/python/.virtualenvs/flask/local/lib/python2.7/site-packages/flask/app.py", line 1813, in full_dispatch_request
    rv = self.dispatch_request()
  File "/home/python/.virtualenvs/flask/local/lib/python2.7/site-packages/flask/app.py", line 1799, in dispatch_request
    return self.view_functions[rule.endpoint](**req.view_args)
  File "/home/python/workspace/microblog/app/auth/routes.py", line 60, in reset_password_request
    send_password_reset_email(user)
  File "/home/python/workspace/microblog/app/auth/email.py", line 7, in send_password_reset_email
    token = user.get_reset_password_token()
  File "/home/python/workspace/microblog/app/models.py", line 69, in get_reset_password_token
    app.config['SECRET_KEY'], algorithm='HS256').decode('utf-8')
NameError: global name 'app' is not defined
2019-04-02 12:51:13,700 INFO: Microblog startup [in /home/python/workspace/microblog/app/__init__.py:85]
2019-04-02 12:51:16,892 ERROR: Exception on /auth/reset_password_request [POST] [in /home/python/.virtualenvs/flask/local/lib/python2.7/site-packages/flask/app.py:1761]
Traceback (most recent call last):
  File "/home/python/.virtualenvs/flask/local/lib/python2.7/site-packages/flask/app.py", line 2292, in wsgi_app
    response = self.full_dispatch_request()
  File "/home/python/.virtualenvs/flask/local/lib/python2.7/site-packages/flask/app.py", line 1815, in full_dispatch_request
    rv = self.handle_user_exception(e)
  File "/home/python/.virtualenvs/flask/local/lib/python2.7/site-packages/flask/app.py", line 1718, in handle_user_exception
    reraise(exc_type, exc_value, tb)
  File "/home/python/.virtualenvs/flask/local/lib/python2.7/site-packages/flask/app.py", line 1813, in full_dispatch_request
    rv = self.dispatch_request()
  File "/home/python/.virtualenvs/flask/local/lib/python2.7/site-packages/flask/app.py", line 1799, in dispatch_request
    return self.view_functions[rule.endpoint](**req.view_args)
  File "/home/python/workspace/microblog/app/auth/routes.py", line 60, in reset_password_request
    send_password_reset_email(user)
  File "/home/python/workspace/microblog/app/auth/email.py", line 14, in send_password_reset_email
    user=user, token=token))
  File "/home/python/.virtualenvs/flask/local/lib/python2.7/site-packages/flask/templating.py", line 134, in render_template
    return _render(ctx.app.jinja_env.get_or_select_template(template_name_or_list),
  File "/home/python/.virtualenvs/flask/local/lib/python2.7/site-packages/jinja2/environment.py", line 869, in get_or_select_template
    return self.get_template(template_name_or_list, parent, globals)
  File "/home/python/.virtualenvs/flask/local/lib/python2.7/site-packages/jinja2/environment.py", line 830, in get_template
    return self._load_template(name, self.make_globals(globals))
  File "/home/python/.virtualenvs/flask/local/lib/python2.7/site-packages/jinja2/environment.py", line 804, in _load_template
    template = self.loader.load(self, name, globals)
  File "/home/python/.virtualenvs/flask/local/lib/python2.7/site-packages/jinja2/loaders.py", line 113, in load
    source, filename, uptodate = self.get_source(environment, name)
  File "/home/python/.virtualenvs/flask/local/lib/python2.7/site-packages/flask/templating.py", line 58, in get_source
    return self._get_source_fast(environment, template)
  File "/home/python/.virtualenvs/flask/local/lib/python2.7/site-packages/flask/templating.py", line 86, in _get_source_fast
    raise TemplateNotFound(template)
TemplateNotFound: email/reset_password.html
2019-04-02 12:52:44,223 INFO: Microblog startup [in /home/python/workspace/microblog/app/__init__.py:85]
